load python/3.7.2  : OK 
load ct_tools/2.18  : OK 
unload python/3.7.2  : OK 
load python/3.7.2  : OK 
unload ct_tools/2.18  : OK 
load ct_tools/2.18  : OK 
/work/ALT/odatis/seaice/users/laforga/projet_cryo2ice/code/common_functions.py:257: RuntimeWarning: invalid value encountered in arccos
  dist = earthradius_fct_of_lat(latDeg1)*np.arccos( np.sin(deg_to_rad(latDeg1))*np.sin(deg_to_rad(latDeg2)) + np.cos(deg_to_rad(latDeg1))*np.cos(deg_to_rad(latDeg2))*np.cos(deg_to_rad(lonDeg2 - lonDeg1)) )
Traceback (most recent call last):
  File "sortnsave_cryo2ice_xings.py", line 1874, in <module>
    data_dict['CS2'],cs2_info_dict = concatenate_cs2_data(date_list,file_dict_colloc['CS2'],common_data_list)
  File "sortnsave_cryo2ice_xings.py", line 775, in concatenate_cs2_data
    data_param[:ind.size,idx] = param[ind].reshape((ind.size,))
  File "/softs/rh7/Python/3.7.2/lib/python3.7/site-packages/numpy-1.16.1-py3.7-linux-x86_64.egg/numpy/ma/core.py", line 3329, in __setitem__
    _data[indx] = dval
ValueError: could not broadcast input array from shape (26) into shape (25)
