load python/3.7.2  : OK 
load ct_tools/2.18  : OK 
unload python/3.7.2  : OK 
load python/3.7.2  : OK 
unload ct_tools/2.18  : OK 
load ct_tools/2.18  : OK 
/work/ALT/odatis/seaice/users/laforga/projet_cryo2ice/code/common_functions.py:257: RuntimeWarning: invalid value encountered in arccos
  dist = earthradius_fct_of_lat(latDeg1)*np.arccos( np.sin(deg_to_rad(latDeg1))*np.sin(deg_to_rad(latDeg2)) + np.cos(deg_to_rad(latDeg1))*np.cos(deg_to_rad(latDeg2))*np.cos(deg_to_rad(lonDeg2 - lonDeg1)) )
Traceback (most recent call last):
  File "sortnsave_cryo2ice_xings.py", line 2152, in <module>
    data_dict['IS2'],is2_info_dict = concatenate_is2_data(date_list,file_dict_colloc['IS2'],common_data_list)
  File "sortnsave_cryo2ice_xings.py", line 1591, in concatenate_is2_data
    is2_data_dict[gdr][b]['latfull'].append(lat_i)
KeyError: 'gt1r'
